Workbook

Sheet Sniper Rifles
B2: Sniper Rifle | D2: Shots To Kill Target | L2: Rate of Fire | O2: TTK | Q2: T1 Damage | S2: Magazine | Y2: Reload | Z2: Aim Delay | AA2: Aim Sens.
D3: Unidad Heavy Tier 1 | H3: Unidad Heavy Non-Tier
D4: Semi-Auto | F4: Full-Auto | H4: Semi-Auto | J4: Full-Auto | L4: RPM | M4: RPS | N4: Inter. | O4: T1 | P4: No Tier | Q4: Semi | R4: Full | S4: St. | U4: Ex. | W4: La. | Y4: Base | Z4: Base | AA4: Base
D5: Head | E5: Body | F5: Head | G5: Body | H5: Head | I5: Body | J5: Head | K5: Body | Y5: 1 | Z5: 1 | AA5: 1
B6: Customizable Sniper Rifles
B7: M40A5 | C7: Short Barrel | D7: 1 | E7: 2 | F7: N/A | H7: 1 | I7: 2 | J7: N/A | L7: 29.3 (2.05s) | M7: =1/2.05 -> 0.48780488 | N7: 2.05 | O7: 2.05 | P7: 2.05 | Q7: - | R7: N/A | S7: 10 | V7: 20 | Y7: - | Z7: - | AA7: -
C8: Standard Barrel | D8: 1 | E8: 2 | H8: 1 | I8: 2 | O8: 2.05 | P8: 2.05 | Q8: - | Y8: 4.35 | Z8: - | AA8: -
C9: Long Barrel | D9: 1 | E9: 2 | H9: 1 | I9: 1 | O9: 2.05 | P9: one-hit | Q9: - | Z9: - | AA9: -
B10: M1891 | C10: Standard Barrel | D10: 1 | E10: 2 | F10: N/A | H10: 1 | I10: 1 | J10: N/A | L10: 28.8 (2.08s) | M10: =28.8/60 -> 0.48 | N10: 2.08 | O10: 2.08 | P10: one-hit | Q10: - | R10: N/A | S10: 10 | V10: 20 | Y10: 4 | Z10: - | AA10: -
C11: Long Barrel | D11: 1 | E11: 2 | H11: 1 | I11: 1 | O11: 2.08 | P11: one-hit | Q11: - | Z11: - | AA11: -
B12: SRSA1 | C12: Standard Barrel | D12: 1 | E12: 2 | F12: N/A | H12: 1 | I12: 1 | J12: N/A | L12: 27.9 (2.15s) | M12: =1/2.15 -> 0.46511628 | N12: 2.15 | O12: 2.15 | P12: one-hit | Q12: - | R12: N/A | S12: 5 | V12: 10 | Y12: 4 | Z12: - | AA12: -
C13: Long Barrel | D13: 1 | E13: 2 | H13: 1 | I13: 1 | O13: 2.15 | P13: one-hit | Q13: - | Z13: - | AA13: -
B14: SR1 | C14: Standard Barrel | D14: 1 | E14: 2 | F14: N/A | H14: 1 | I14: 1 | J14: N/A | L14: 27.1 (2.22s) | M14: =1/2.22 -> 0.45045045 | N14: 2.22 | O14: 2.22 | P14: one-hit | Q14: - | R14: N/A | S14: 5 | V14: 10 | Y14: 3.95 | Z14: - | AA14: -
C15: Long Barrel | D15: 1 | E15: 2 | H15: 1 | I15: 1 | O15: 2.22 | P15: one-hit | Q15: - | Z15: - | AA15: -
B16: L115A3 | C16: Standard Barrel | D16: 1 | E16: 2 | F16: N/A | H16: 1 | I16: 1 | J16: N/A | L16: 27.9 (2.15s) | M16: =1/2.15 -> 0.46511628 | N16: 2.15 | O16: 2.15 | P16: one-hit | Q16: - | R16: N/A | S16: 5 | V16: 10 | Y16: 4.35 | Z16: - | AA16: -
C17: Long Barrel | D17: 1 | E17: 2 | H17: 1 | I17: 1 | O17: 2.15 | P17: one-hit | Q17: - | Z17: - | AA17: -
B18: MSR | C18: Short Barrel | D18: 1 | E18: 2 | F18: N/A | H18: 1 | I18: 1 | J18: N/A | L18: 26.1 (2.3s) | M18: =1/2.3 -> 0.43478261 | N18: 2.3 | O18: 2.3 | P18: one-hit | Q18: - | R18: N/A | S18: 5 | V18: 10 | Y18: - | Z18: - | AA18: -
C19: Standard Barrel | D19: 1 | E19: 2 | H19: 1 | I19: 1 | O19: 2.3 | P19: one-hit | Q19: - | Y19: 4.35 | Z19: - | AA19: -
C20: Long Barrel | D20: 1 | E20: 1 | H20: 1 | I20: 1 | O20: one-hit | P20: one-hit | Q20: - | Z20: - | AA20: -
B21: HTI | C21: Standard Barrel | D21: 1 | E21: 1 | F21: N/A | H21: 1 | I21: 1 | J21: N/A | L21: 25.5 (2.35s) | M21: =1/2.35 -> 0.42553191 | N21: 2.35 | O21: one-hit | P21: one-hit | Q21: - | R21: N/A | S21: 5 | Y21: 3.95 | Z21: - | AA21: -
C22: Long Barrel | D22: 1 | E22: 1 | H22: 1 | I22: 1 | O22: one-hit | P22: one-hit | Q22: - | Z22: - | AA22: -
B23: SR25 | C23: Short Barrel | D23: 2 | E23: 4 | F23: N/A | H23: 1 | I23: 3 | J23: N/A | L23: - | M23: - | N23: - | O23: - | P23: - | Q23: - | R23: N/A | S23: 10 | V23: 20 | Y23: - | Z23: - | AA23: -
C24: Standard Barrel | D24: 2 | E24: 4 | H24: 1 | I24: 2 | O24: - | P24: - | Q24: - | Y24: 1.97 | Z24: - | AA24: -
B25: Dragunov | C25: Short Barrel | D25: 2 | E25: 5 | F25: N/A | H25: 2 | I25: 3 | J25: N/A | L25: - | M25: - | N25: - | O25: - | P25: - | Q25: - | R25: N/A | S25: 10 | V25: 20 | Y25: - | Z25: - | AA25: -
C26: Standard Barrel | D26: 2 | E26: 4 | H26: 1 | I26: 3 | O26: - | P26: - | Q26: - | Y26: 2.55 | Z26: - | AA26: -
B27: Mk14 | C27: Standard Barrel | D27: 3 | E27: 7 | F27: 4 | G27: 9 | H27: 2 | I27: 5 | J27: 3 | K27: 6 | L27: 705 | M27: =L27/60 -> 11.75 | N27: =60/L27 -> 0.085106383 | O27: =4*60/L27 -> 0.34042553 | P27: =2*60/L27 -> 0.17021277 | Q27: - | R27: - | S27: 10 | V27: 20 | Y27: 2.45 | Z27: - | AA27: -
C28: Long Barrel | D28: 3 | E28: 7 | F28: 4 | G28: 9 | H28: 2 | I28: 4 | J28: 3 | K28: 5 | O28: =3*60/L27 -> 0.25531915 | P28: =2*60/L27 -> 0.17021277 | Q28: - | R28: - | Z28: - | AA28: -
B29: G28 | C29: Standard Barrel | D29: 4 | E29: 10 | F29: N/A | H29: 3 | I29: 6 | J29: N/A | L29: - | M29: - | N29: - | O29: - | P29: - | Q29: - | R29: N/A | S29: 10 | V29: 20 | Y29: 1.97 | Z29: - | AA29: -
C30: Long Barrel | D30: 4 | E30: 9 | H30: 3 | I30: 5 | O30: - | P30: - | Q30: - | Z30: - | AA30: -
B31: Fallen Ghosts
B32: PSG-1 | C32: Standard Barrel | D32: 4 | E32: 10 | F32: N/A | H32: 3 | I32: 6 | J32: N/A | L32: - | M32: - | N32: - | O32: - | P32: - | Q32: - | R32: N/A | S32: 10 | V32: 20 | Y32: 1.97 | Z32: - | AA32: -
C33: Long Barrel | D33: 4 | E33: 9 | H33: 3 | I33: 5 | O33: - | P33: - | Q33: - | Z33: - | AA33: -
B34: BFG-50A | C34: Standard Barrel | D34: 1 | E34: 1 | F34: N/A | H34: 1 | I34: 1 | J34: N/A | L34: - | M34: - | N34: - | O34: one-hit | P34: one-hit | Q34: - | R34: N/A | S34: 5 | Y34: 3.95 | Z34: - | AA34: -
C35: Long Barrel | D35: 1 | E35: 1 | H35: 1 | I35: 1 | O35: one-hit | P35: one-hit | Q35: - | Z35: - | AA35: -
B36: Other
B37: TAC-50 | C37: Standard Barrel | D37: 1 | E37: 1 | F37: N/A | H37: 1 | I37: 1 | J37: N/A | L37: 25.5 | M37: =1/2.35 -> 0.42553191 | N37: 2.35 | O37: one-hit | P37: one-hit | Q37: - | R37: N/A | S37: 5 | Y37: 3.95 | Z37: - | AA37: -
B38: R93 LRS2 | C38: Short Barrel | D38: 1 | E38: 2 | F38: N/A | H38: 1 | I38: 1 | J38: N/A | L38: 26.1 | M38: =1/2.3 -> 0.43478261 | N38: 2.3 | O38: 2.3 | P38: one-hit | Q38: - | R38: N/A | S38: 5 | V38: 10 | Y38: - | Z38: - | AA38: -
C39: Standard Barrel | D39: 1 | E39: 2 | H39: 1 | I39: 1 | O39: 2.3 | P39: one-hit | Q39: - | Y39: 4.35 | Z39: - | AA39: -
C40: Long Barrel | D40: 1 | E40: 1 | H40: 1 | I40: 1 | O40: one-hit | P40: one-hit | Q40: - | Z40: - | AA40: -
B41: FRF-2 | C41: Standard Barrel | D41: - | E41: - | F41: N/A | H41: - | I41: - | J41: N/A | L41: - | M41: - | N41: - | O41: - | P41: - | Q41: - | R41: N/A | S41: - | V41: 10 | Y41: - | Z41: - | AA41: -
...

Sheet Assault Rifles
B2: Assault Rifles | D2: Shots To Kill Target | L2: Rate of Fire | O2: TTK | Q2: T1 Damage | S2: Magazine | Y2: Reload | Z2: Aim Delay | AA2: Aim Sens.
D3: Unidad Heavy Tier 1 | H3: Unidad Heavy Non-Tier
D4: Semi-Auto | F4: Full-Auto | H4: Semi-Auto | J4: Full-Auto | L4: RPM | M4: RPS | N4: Inter. | O4: T1 | P4: No Tier | Q4: Semi | R4: Full | S4: St. | U4: Ex. | W4: La. | Y4: Base | Z4: Base | AA4: Base
D5: Head | E5: Body | F5: Head | G5: Body | H5: Head | I5: Body | J5: Head | K5: Body | Y5: 1 | Z5: 1 | AA5: 1
B6: Customizable Assault Rifles
B7: P416 | C7: Short Barrel | D7: 3 | E7: 7 | F7: 4 | G7: 9 | H7: 3 | I7: 7 | J7: 4 | K7: 10 | L7: 735 | M7: =L7/60 -> 12.25 | N7: =60/L7 -> 0.081632653 | O7: =60*3/L7 -> 0.24489796 | P7: =IFS(OR(K7="-",ISBLANK(K7)),"-",K7<1,"one-hit",K7<=3,60/L7,OR(K7=4,K7=7,K7=9),"manual",K7<7,2*60/L7,K7<9,3*60/L7,K7<=11,4*60/L7,K7>11,"???") -> 0.32653061 | Q7: - | R7: - | S7: 20 | U7: 30 | W7: 50 | Y7: - | Z7: - | AA7: -
C8: Standard Barrel | D8: 3 | E8: 6 | F8: 4 | G8: 8 | H8: 3 | I8: 7 | J8: 4 | K8: 9 | O8: =IFS(OR(G8="-",ISBLANK(G8)),"-",G8<1,"one-hit",G8<=3,60/L7,OR(G8=4,G8=7,G8=9),"manual",G8<7,2*60/L7,G8<9,3*60/L7,G8<=11,4*60/L7,G8>11,"???") -> 0.24489796 | P8: =IFS(OR(K8="-",ISBLANK(K8)),"-",K8<1,"one-hit",K8<=3,60/L7,OR(K8=4,K8=7,K8=9),"manual",K8<7,2*60/L7,K8<9,3*60/L7,K8<=11,4*60/L7,K8>11,"???") -> manual | Q8: - | R8: - | Y8: 1.97 | Z8: - | AA8: -
B9: SR3M | C9: Standard Barrel | D9: 3 | E9: 7 | F9: 3 | G9: 8 | H9: 3 | I9: 7 | J9: 4 | K9: 9 | L9: 877 | M9: =L9/60 -> 14.616667 | N9: =60/L9 -> 0.068415051 | O9: =IFS(OR(G9="-",ISBLANK(G9)),"-",G9<1,"one-hit",G9<=3,60/L9,OR(G9=4,G9=7,G9=9),"manual",G9<7,2*60/L9,G9<9,3*60/L9,G9<=11,4*60/L9,G9>11,"???") -> 0.20524515 | P9: =IFS(OR(K9="-",ISBLANK(K9)),"-",K9<1,"one-hit",K9<=3,60/L9,OR(K9=4,K9=7,K9=9),"manual",K9<7,2*60/L9,K9<9,3*60/L9,K9<=11,4*60/L9,K9>11,"???") -> manual | Q9: - | R9: - | S9: 20 | V9: 30 | Y9: 2.27 | Z9: - | AA9: -
C10: Long Barrel | D10: 3 | E10: 6 | F10: 3 | G10: 7 | H10: 3 | I10: 7 | J10: 4 | K10: 8 | O10: =60*3/L9 -> 0.20524515 | P10: =IFS(OR(K10="-",ISBLANK(K10)),"-",K10<1,"one-hit",K10<=3,60/L9,OR(K10=4,K10=7,K10=9),"manual",K10<7,2*60/L9,K10<9,3*60/L9,K10<=11,4*60/L9,K10>11,"???") -> 0.20524515 | Q10: - | R10: - | Z10: - | AA10: -
B11: AK-12 | C11: Standard Barrel | D11: 3 | E11: 5 | F11: 3 | G11: 7 | H11: 3 | I11: 6 | J11: 3 | K11: 7 | L11: 844 | M11: =L11/60 -> 14.066667 | N11: =60/L11 -> 0.071090047 | O11: =60*3/L11 -> 0.21327014 | P11: =IFS(OR(K11="-",ISBLANK(K11)),"-",K11<1,"one-hit",K11<=3,60/L11,OR(K11=4,K11=7,K11=9),"manual",K11<7,2*60/L11,K11<9,3*60/L11,K11<=11,4*60/L11,K11>11,"???") -> manual | Q11: - | R11: - | S11: 20 | U11: 30 | W11: 50 | Y11: 1.97 | Z11: - | AA11: -
C12: Long Barrel | D12: 2 | E12: 5 | F12: 3 | G12: 6 | H12: 3 | I12: 5 | J12: 3 | K12: 7 | O12: =IFS(OR(G12="-",ISBLANK(G12)),"-",G12<1,"one-hit",G12<=3,60/L11,OR(G12=4,G12=7,G12=9),"manual",G12<7,2*60/L11,G12<9,3*60/L11,G12<=11,4*60/L11,G12>11,"???") -> 0.14218009 | P12: =IFS(OR(K12="-",ISBLANK(K12)),"-",K12<1,"one-hit",K12<=3,60/L11,OR(K12=4,K12=7,K12=9),"manual",K12<7,2*60/L11,K12<9,3*60/L11,K12<=11,4*60/L11,K12>11,"???") -> manual | Q12: - | R12: - | Z12: - | AA12: -
B13: AUG-A3 | C13: Standard Barrel | D13: 3 | E13: 5 | F13: 3 | G13: 6 | H13: 3 | I13: 6 | J13: 3 | K13: 7 | L13: 682 | M13: =L13/60 -> 11.366667 | N13: =60/L13 -> 0.08797654 | O13: =IFS(OR(G13="-",ISBLANK(G13)),"-",G13<1,"one-hit",G13<=3,60/L13,OR(G13=4,G13=7,G13=9),"manual",G13<7,2*60/L13,G13<9,3*60/L13,G13<=11,4*60/L13,G13>11,"???") -> 0.17595308 | P13: =IFS(OR(K13="-",ISBLANK(K13)),"-",K13<1,"one-hit",K13<=3,60/L13,OR(K13=4,K13=7,K13=9),"manual",K13<7,2*60/L13,K13<9,3*60/L13,K13<=11,4*60/L13,K13>11,"???") -> manual | Q13: - | R13: - | S13: 20 | V13: 30 | Y13: 1.97 | Z13: - | AA13: -
C14: Long Barrel | D14: 2 | E14: 5 | F14: 3 | G14: 6 | H14: 3 | I14: 5 | J14: 3 | K14: 7 | O14: =IFS(OR(G14="-",ISBLANK(G14)),"-",G14<1,"one-hit",G14<=3,60/L13,OR(G14=4,G14=7,G14=9),"manual",G14<7,2*60/L13,G14<9,3*60/L13,G14<=11,4*60/L13,G14>11,"???") -> 0.17595308 | P14: =IFS(OR(K14="-",ISBLANK(K14)),"-",K14<1,"one-hit",K14<=3,60/L13,OR(K14=4,K14=7,K14=9),"manual",K14<7,2*60/L13,K14<9,3*60/L13,K14<=11,4*60/L13,K14>11,"???") -> manual | Q14: - | R14: - | Z14: - | AA14: -
B15: 556xi | C15: Short Barrel | D15: 3 | E15: 7 | F15: 4 | G15: 8 | H15: 3 | I15: 7 | J15: 4 | K15: 10 | L15: 732 | M15: =L15/60 -> 12.2 | N15: =60/L15 -> 0.081967213 | O15: =IFS(OR(G15="-",ISBLANK(G15)),"-",G15<1,"one-hit",G15<=3,60/L15,OR(G15=4,G15=7,G15=9),"manual",G15<7,2*60/L15,G15<9,3*60/L15,G15<=11,4*60/L15,G15>11,"???") -> 0.24590164 | P15: =IFS(OR(K15="-",ISBLANK(K15)),"-",K15<1,"one-hit",K15<=3,60/L15,OR(K15=4,K15=7,K15=9),"manual",K15<7,2*60/L15,K15<9,3*60/L15,K15<=11,4*60/L15,K15>11,"???") -> 0.32786885 | Q15: - | R15: - | S15: 20 | U15: 30 | W15: 50 | Y15: - | Z15: - | AA15: -
C16: Standard Barrel | D16: 3 | E16: 6 | F16: 3 | G16: 7 | H16: 3 | I16: 7 | J16: 4 | K16: 8 | O16: =60*3/L15 -> 0.24590164 | P16: =IFS(OR(K16="-",ISBLANK(K16)),"-",K16<1,"one-hit",K16<=3,60/L15,OR(K16=4,K16=7,K16=9),"manual",K16<7,2*60/L15,K16<9,3*60/L15,K16<=11,4*60/L15,K16>11,"???") -> 0.24590164 | Q16: - | R16: - | Y16: 2.27 | Z16: - | AA16: -
C17: Long Barrel | D17: 3 | E17: 6 | F17: 3 | G17: 7 | H17: 3 | I17: 6 | J17: 3 | K17: 7 | O17: =60*3/L15 -> 0.24590164 | P17: =IFS(OR(K17="-",ISBLANK(K17)),"-",K17<1,"one-hit",K17<=3,60/L15,OR(K17=4,K17=7,K17=9),"manual",K17<7,2*60/L15,K17<9,3*60/L15,K17<=11,4*60/L15,K17>11,"???") -> manual | Q17: - | R17: - | Z17: - | AA17: -
B18: 805 Bren A2 | C18: Short Barrel | D18: 3 | E18: 6 | F18: 3 | G18: 7 | H18: 3 | I18: 6 | J18: 4 | K18: 8 | L18: 732 | M18: =L18/60 -> 12.2 | N18: =60/L18 -> 0.081967213 | O18: =60*3/L18 -> 0.24590164 | P18: =IFS(OR(K18="-",ISBLANK(K18)),"-",K18<1,"one-hit",K18<=3,60/L18,OR(K18=4,K18=7,K18=9),"manual",K18<7,2*60/L18,K18<9,3*60/L18,K18<=11,4*60/L18,K18>11,"???") -> 0.24590164 | Q18: - | R18: - | S18: 20 | U18: 30 | W18: 50 | Y18: - | Z18: - | AA18: -
C19: Standard Barrel | D19: 3 | E19: 5 | F19: 3 | G19: 6 | H19: 3 | I19: 6 | J19: 3 | K19: 7 | O19: =IFS(OR(G19="-",ISBLANK(G19)),"-",G19<1,"one-hit",G19<=3,60/L18,OR(G19=4,G19=7,G19=9),"manual",G19<7,2*60/L18,G19<9,3*60/L18,G19<=11,4*60/L18,G19>11,"???") -> 0.16393443 | P19: =IFS(OR(K19="-",ISBLANK(K19)),"-",K19<1,"one-hit",K19<=3,60/L18,OR(K19=4,K19=7,K19=9),"manual",K19<7,2*60/L18,K19<9,3*60/L18,K19<=11,4*60/L18,K19>11,"???") -> manual | Q19: - | R19: - | Y19: 1.97 | Z19: - | AA19: -
C20: Long Barrel | D20: 2 | E20: 5 | F20: 3 | G20: 6 | H20: 3 | I20: 5 | J20: 3 | K20: 7 | O20: =IFS(OR(G20="-",ISBLANK(G20)),"-",G20<1,"one-hit",G20<=3,60/L18,OR(G20=4,G20=7,G20=9),"manual",G20<7,2*60/L18,G20<9,3*60/L18,G20<=11,4*60/L18,G20>11,"???") -> 0.16393443 | P20: =IFS(OR(K20="-",ISBLANK(K20)),"-",K20<1,"one-hit",K20<=3,60/L18,OR(K20=4,K20=7,K20=9),"manual",K20<7,2*60/L18,K20<9,3*60/L18,K20<=11,4*60/L18,K20>11,"???") -> manual | Q20: - | R20: - | Z20: - | AA20: -
B21: G2 | C21: Short Barrel | D21: 3 | E21: 7 | F21: 4 | G21: 9 | H21: 3 | I21: 7 | J21: 4 | K21: 10 | L21: 970 | M21: =L21/60 -> 16.166667 | N21: =60/L21 -> 0.06185567 | O21: =60*3/L21 -> 0.18556701 | P21: =IFS(OR(K21="-",ISBLANK(K21)),"-",K21<1,"one-hit",K21<=3,60/L21,OR(K21=4,K21=7,K21=9),"manual",K21<7,2*60/L21,K21<9,3*60/L21,K21<=11,4*60/L21,K21>11,"???") -> 0.24742268 | Q21: - | R21: - | S21: 20 | U21: 30 | W21: 50 | Y21: - | Z21: - | AA21: -
C22: Standard Barrel | D22: 3 | E22: 6 | F22: 4 | G22: 8 | H22: 3 | I22: 7 | J22: 4 | K22: 9 | O22: =IFS(OR(G22="-",ISBLANK(G22)),"-",G22<1,"one-hit",G22<=3,60/L21,OR(G22=4,G22=7,G22=9),"manual",G22<7,2*60/L21,G22<9,3*60/L21,G22<=11,4*60/L21,G22>11,"???") -> 0.18556701 | P22: =IFS(OR(K22="-",ISBLANK(K22)),"-",K22<1,"one-hit",K22<=3,60/L21,OR(K22=4,K22=7,K22=9),"manual",K22<7,2*60/L21,K22<9,3*60/L21,K22<=11,4*60/L21,K22>11,"???") -> manual | Q22: - | R22: - | Y22: 1.97 | Z22: - | AA22: -
B23: L85A2 | C23: Short Barrel | D23: 3 | E23: 6 | F23: 3 | G23: 7 | H23: 3 | I23: 6 | J23: 3 | K23: 7 | L23: 695 | M23: =L23/60 -> 11.583333 | N23: =60/L23 -> 0.086330935 | O23: =60*3/L23 -> 0.25899281 | P23: =IFS(OR(K23="-",ISBLANK(K23)),"-",K23<1,"one-hit",K23<=3,60/L23,OR(K23=4,K23=7,K23=9),"manual",K23<7,2*60/L23,K23<9,3*60/L23,K23<=11,4*60/L23,K23>11,"???") -> manual | Q23: - | R23: - | S23: 20 | U23: 30 | W23: 50 | Y23: - | Z23: - | AA23: -
C24: Standard Barrel | D24: 2 | E24: 5 | F24: 3 | G24: 6 | H24: 3 | I24: 6 | J24: 3 | K24: 7 | O24: =IFS(OR(G24="-",ISBLANK(G24)),"-",G24<1,"one-hit",G24<=3,60/L23,OR(G24=4,G24=7,G24=9),"manual",G24<7,2*60/L23,G24<9,3*60/L23,G24<=11,4*60/L23,G24>11,"???") -> 0.17266187 | P24: =IFS(OR(K24="-",ISBLANK(K24)),"-",K24<1,"one-hit",K24<=3,60/L23,OR(K24=4,K24=7,K24=9),"manual",K24<7,2*60/L23,K24<9,3*60/L23,K24<=11,4*60/L23,K24>11,"???") -> manual | Q24: - | R24: - | Y24: 2.27 | Z24: - | AA24: -
B25: R5 | C25: Standard Barrel | D25: N/A | F25: 3 | G25: 6 | H25: N/A | J25: 3 | K25: 7 | L25: 620 | M25: =L25/60 -> 10.333333 | N25: =60/L25 -> 0.096774194 | O25: =IFS(OR(G25="-",ISBLANK(G25)),"-",G25<1,"one-hit",G25<=3,60/L25,OR(G25=4,G25=7,G25=9),"manual",G25<7,2*60/L25,G25<9,3*60/L25,G25<=11,4*60/L25,G25>11,"???") -> 0.19354839 | P25: =IFS(OR(K25="-",ISBLANK(K25)),"-",K25<1,"one-hit",K25<=3,60/L25,OR(K25=4,K25=7,K25=9),"manual",K25<7,2*60/L25,K25<9,3*60/L25,K25<=11,4*60/L25,K25>11,"???") -> manual | Q25: - | R25: - | S25: 20 | U25: 30 | W25: 50 | Y25: 2.18 | Z25: - | AA25: -
C26: Long Barrel | F26: 3 | G26: 5 | J26: 3 | K26: 6 | O26: =IFS(OR(G26="-",ISBLANK(G26)),"-",G26<1,"one-hit",G26<=3,60/L25,OR(G26=4,G26=7,G26=9),"manual",G26<7,2*60/L25,G26<9,3*60/L25,G26<=11,4*60/L25,G26>11,"???") -> 0.19354839 | P26: =IFS(OR(K26="-",ISBLANK(K26)),"-",K26<1,"one-hit",K26<=3,60/L25,OR(K26=4,K26=7,K26=9),"manual",K26<7,2*60/L25,K26<9,3*60/L25,K26<=11,4*60/L25,K26>11,"???") -> 0.19354839 | Q26: - | R26: - | Z26: - | AA26: -
B27: AK-47 | C27: Short Barrel | D27: 3 | E27: 5 | F27: 3 | G27: 7 | H27: 3 | I27: 6 | J27: 3 | K27: 7 | L27: 588 | M27: =L27/60 -> 9.8 | N27: =60/L27 -> 0.10204082 | O27: =60*3/L27 -> 0.30612245 | P27: =IFS(OR(K27="-",ISBLANK(K27)),"-",K27<1,"one-hit",K27<=3,60/L27,OR(K27=4,K27=7,K27=9),"manual",K27<7,2*60/L27,K27<9,3*60/L27,K27<=11,4*60/L27,K27>11,"???") -> manual | Q27: - | R27: - | S27: 20 | U27: 30 | W27: 50 | Y27: - | Z27: - | AA27: -
C28: Standard Barrel | D28: 2 | E28: 5 | F28: 3 | G28: 6 | H28: 3 | I28: 5 | J28: 3 | K28: 7 | O28: =IFS(OR(G28="-",ISBLANK(G28)),"-",G28<1,"one-hit",G28<=3,60/L27,OR(G28=4,G28=7,G28=9),"manual",G28<7,2*60/L27,G28<9,3*60/L27,G28<=11,4*60/L27,G28>11,"???") -> 0.20408163 | P28: =IFS(OR(K28="-",ISBLANK(K28)),"-",K28<1,"one-hit",K28<=3,60/L27,OR(K28=4,K28=7,K28=9),"manual",K28<7,2*60/L27,K28<9,3*60/L27,K28<=11,4*60/L27,K28>11,"???") -> manual | Q28: - | R28: - | Y28: 2.27 | Z28: - | AA28: -
C29: Long Barrel | D29: 2 | E29: 5 | F29: 3 | G29: 6 | H29: 2 | I29: 5 | J29: 3 | K29: 6 | O29: =IFS(OR(G29="-",ISBLANK(G29)),"-",G29<1,"one-hit",G29<=3,60/L27,OR(G29=4,G29=7,G29=9),"manual",G29<7,2*60/L27,G29<9,3*60/L27,G29<=11,4*60/L27,G29>11,"???") -> 0.20408163 | P29: =IFS(OR(K29="-",ISBLANK(K29)),"-",K29<1,"one-hit",K29<=3,60/L27,OR(K29=4,K29=7,K29=9),"manual",K29<7,2*60/L27,K29<9,3*60/L27,K29<=11,4*60/L27,K29>11,"???") -> 0.20408163 | Q29: - | R29: - | Z29: - | AA29: -
B30: M4A1 | C30: Standard Barrel | D30: 3 | E30: 6 | F30: 3 | G30: 7 | H30: 3 | I30: 6 | J30: 3 | K30: 7 | L30: 882 | M30: =L30/60 -> 14.7 | N30: =60/L30 -> 0.068027211 | O30: =60*3/L30 -> 0.20408163 | P30: =IFS(OR(K30="-",ISBLANK(K30)),"-",K30<1,"one-hit",K30<=3,60/L30,OR(K30=4,K30=7,K30=9),"manual",K30<7,2*60/L30,K30<9,3*60/L30,K30<=11,4*60/L30,K30>11,"???") -> manual | Q30: - | R30: - | S30: 20 | U30: 30 | W30: 50 | Y30: 1.97 | Z30: - | AA30: -
C31: Long Barrel | D31: 3 | E31: 5 | F31: 3 | G31: 6 | H31: 3 | I31: 6 | J31: 3 | K31: 7 | O31: =IFS(OR(G31="-",ISBLANK(G31)),"-",G31<1,"one-hit",G31<=3,60/L30,OR(G31=4,G31=7,G31=9),"manual",G31<7,2*60/L30,G31<9,3*60/L30,G31<=11,4*60/L30,G31>11,"???") -> 0.13605442 | P31: =IFS(OR(K31="-",ISBLANK(K31)),"-",K31<1,"one-hit",K31<=3,60/L30,OR(K31=4,K31=7,K31=9),"manual",K31<7,2*60/L30,K31<9,3*60/L30,K31<=11,4*60/L30,K31>11,"???") -> manual | Q31: - | R31: - | Z31: - | AA31: -
B32: Mk17 | C32: Short Barrel | D32: 2 | E32: 5 | F32: 3 | G32: 6 | H32: 2 | I32: 5 | J32: 3 | K32: 6 | L32: 610 | M32: =L32/60 -> 10.166667 | N32: =60/L32 -> 0.098360656 | O32: =IFS(OR(G32="-",ISBLANK(G32)),"-",G32<1,"one-hit",G32<=3,60/L32,OR(G32=4,G32=7,G32=9),"manual",G32<7,2*60/L32,G32<9,3*60/L32,G32<=11,4*60/L32,G32>11,"???") -> 0.19672131 | P32: =IFS(OR(K32="-",ISBLANK(K32)),"-",K32<1,"one-hit",K32<=3,60/L32,OR(K32=4,K32=7,K32=9),"manual",K32<7,2*60/L32,K32<9,3*60/L32,K32<=11,4*60/L32,K32>11,"???") -> 0.19672131 | Q32: - | R32: - | S32: 20 | V32: 30 | Y32: - | Z32: - | AA32: -
C33: Standard Barrel | D33: 2 | E33: 4 | F33: 3 | G33: 5 | H33: 2 | I33: 5 | J33: 3 | K33: 6 | O33: =IFS(OR(G33="-",ISBLANK(G33)),"-",G33<1,"one-hit",G33<=3,60/L32,OR(G33=4,G33=7,G33=9),"manual",G33<7,2*60/L32,G33<9,3*60/L32,G33<=11,4*60/L32,G33>11,"???") -> 0.19672131 | P33: =IFS(OR(K33="-",ISBLANK(K33)),"-",K33<1,"one-hit",K33<=3,60/L32,OR(K33=4,K33=7,K33=9),"manual",K33<7,2*60/L32,K33<9,3*60/L32,K33<=11,4*60/L32,K33>11,"???") -> 0.19672131 | Q33: - | R33: - | Y33: 2.95 | Z33: - | AA33: -
C34: Long Barrel | D34: 2 | E34: 4 | F34: 3 | G34: 5 | H34: 2 | I34: 4 | J34: 3 | K34: 5 | O34: =IFS(OR(G34="-",ISBLANK(G34)),"-",G34<1,"one-hit",G34<=3,60/L32,OR(G34=4,G34=7,G34=9),"manual",G34<7,2*60/L32,G34<9,3*60/L32,G34<=11,4*60/L32,G34>11,"???") -> 0.19672131 | P34: =IFS(OR(K34="-",ISBLANK(K34)),"-",K34<1,"one-hit",K34<=3,60/L32,OR(K34=4,K34=7,K34=9),"manual",K34<7,2*60/L32,K34<9,3*60/L32,K34<=11,4*60/L32,K34>11,"???") -> 0.19672131 | Q34: - | R34: - | Z34: - | AA34: -
B35: ACR | C35: Short Barrel | D35: 3 | E35: 7 | F35: 4 | G35: 8 | H35: 3 | I35: 7 | J35: 4 | K35: 9 | L35: 780 | M35: =L35/60 -> 13 | N35: =60/L35 -> 0.076923077 | O35: =IFS(OR(G35="-",ISBLANK(G35)),"-",G35<1,"one-hit",G35<=3,60/L35,OR(G35=4,G35=7,G35=9),"manual",G35<7,2*60/L35,G35<9,3*60/L35,G35<=11,4*60/L35,G35>11,"???") -> 0.23076923 | P35: =IFS(OR(K35="-",ISBLANK(K35)),"-",K35<1,"one-hit",K35<=3,60/L35,OR(K35=4,K35=7,K35=9),"manual",K35<7,2*60/L35,K35<9,3*60/L35,K35<=11,4*60/L35,K35>11,"???") -> manual | Q35: - | R35: - | S35: 20 | U35: 30 | W35: 50 | Y35: - | Z35: - | AA35: -
C36: Standard Barrel | D36: 3 | E36: 6 | F36: 3 | G36: 7 | H36: 3 | I36: 6 | J36: 4 | K36: 8 | O36: =60*3/L35 -> 0.23076923 | P36: =IFS(OR(K36="-",ISBLANK(K36)),"-",K36<1,"one-hit",K36<=3,60/L35,OR(K36=4,K36=7,K36=9),"manual",K36<7,2*60/L35,K36<9,3*60/L35,K36<=11,4*60/L35,K36>11,"???") -> 0.23076923 | Q36: - | R36: - | Y36: 1.97 | Z36: - | AA36: -
C37: Long Barrel | D37: 3 | E37: 5 | F37: 3 | G37: 7 | H37: 3 | I37: 6 | J37: 3 | K37: 7 | O37: =60*2/L35 -> 0.15384615 | P37: =IFS(OR(K37="-",ISBLANK(K37)),"-",K37<1,"one-hit",K37<=3,60/L35,OR(K37=4,K37=7,K37=9),"manual",K37<7,2*60/L35,K37<9,3*60/L35,K37<=11,4*60/L35,K37>11,"???") -> manual | Q37: - | R37: - | Z37: - | AA37: -
B38: TAR-21 | C38: Standard Barrel | D38: 3 | E38: 6 | F38: 3 | G38: 7 | H38: 3 | I38: 6 | J38: 4 | K38: 8 | L38: 832 | M38: =L38/60 -> 13.866667 | N38: =60/L38 -> 0.072115385 | O38: =60*3/L38 -> 0.21634615 | P38: =IFS(OR(K38="-",ISBLANK(K38)),"-",K38<1,"one-hit",K38<=3,60/L38,OR(K38=4,K38=7,K38=9),"manual",K38<7,2*60/L38,K38<9,3*60/L38,K38<=11,4*60/L38,K38>11,"???") -> 0.21634615 | Q38: - | R38: - | S38: 20 | U38: 30 | W38: 50 | Y38: 1.97 | Z38: - | AA38: -
C39: Long Barrel | D39: 3 | E39: 5 | F39: 3 | G39: 7 | H39: 3 | I39: 6 | J39: 3 | K39: 7 | O39: =60*2/L38 -> 0.14423077 | P39: =IFS(OR(K39="-",ISBLANK(K39)),"-",K39<1,"one-hit",K39<=3,60/L38,OR(K39=4,K39=7,K39=9),"manual",K39<7,2*60/L38,K39<9,3*60/L38,K39<=11,4*60/L38,K39>11,"???") -> manual | Q39: - | R39: - | Z39: - | AA39: -
B40: G36C | C40: Standard Barrel | D40: 3 | E40: 6 | F40: 3 | G40: 7 | H40: 3 | I40: 6 | J40: 3 | K40: 7 | L40: 735 | M40: =L40/60 -> 12.25 | N40: =60/L40 -> 0.081632653 | O40: =60*3/L40 -> 0.24489796 | P40: =IFS(OR(K40="-",ISBLANK(K40)),"-",K40<1,"one-hit",K40<=3,60/L40,OR(K40=4,K40=7,K40=9),"manual",K40<7,2*60/L40,K40<9,3*60/L40,K40<=11,4*60/L40,K40>11,"???") -> manual | Q40: - | R40: - | S40: 20 | U40: 30 | W40: 50 | Y40: 1.98 | Z40: - | AA40: -
C41: Long Barrel | D41: 3 | E41: 5 | F41: 3 | G41: 6 | H41: 3 | I41: 6 | J41: 3 | K41: 7 | O41: =IFS(OR(G41="-",ISBLANK(G41)),"-",G41<1,"one-hit",G41<=3,60/L40,OR(G41=4,G41=7,G41=9),"manual",G41<7,2*60/L40,G41<9,3*60/L40,G41<=11,4*60/L40,G41>11,"???") -> 0.16326531 | P41: =IFS(OR(K41="-",ISBLANK(K41)),"-",K41<1,"one-hit",K41<=3,60/L40,OR(K41=4,K41=7,K41=9),"manual",K41<7,2*60/L40,K41<9,3*60/L40,K41<=11,4*60/L40,K41>11,"???") -> manual | Q41: - | R41: - | Z41: - | AA41: -
...

Sheet LMGs
B2: Light Machine Guns | D2: Shots To Kill Target | L2: Rate of Fire | O2: TTK | Q2: T1 Damage | S2: Magazine | Y2: Reload | Z2: Aim Delay | AA2: Aim Sens.
D3: Unidad Heavy Tier 1 | H3: Unidad Heavy Non-Tier
D4: Semi-Auto | F4: Full-Auto | H4: Semi-Auto | J4: Full-Auto | L4: RPM | M4: RPS | N4: Inter. | O4: T1 | P4: No Tier | Q4: Semi | R4: Full | S4: St. | U4: Ex. | W4: La. | Y4: Base | Z4: Base | AA4: Base
D5: Head | E5: Body | F5: Head | G5: Body | H5: Head | I5: Body | J5: Head | K5: Body | Y5: 1 | Z5: 1 | AA5: 1
B6: Customizable Light Machine Guns
B7: MG121 | C7: Short Barrel | D7: N/A | F7: 5 | G7: 11 | H7: N/A | J7: 4 | K7: 8 | L7: 702 | M7: =L7/60 -> 11.7 | N7: =60/L7 -> 0.085470085 | O7: =IFS(OR(G7="-",ISBLANK(G7)),"-",G7<1,"one-hit",G7<=3,60/L7,OR(G7=4,G7=7,G7=9),"manual",G7<7,2*60/L7,G7<9,3*60/L7,G7<=11,4*60/L7,G7>11,"???") -> 0.34188034 | P7: =IFS(OR(K7="-",ISBLANK(K7)),"-",K7<1,"one-hit",K7<=3,60/L7,OR(K7=4,K7=7,K7=9),"manual",K7<7,2*60/L7,K7<9,3*60/L7,K7<=11,4*60/L7,K7>11,"???") -> 0.25641026 | Q7: - | R7: - | S7: 90 | Y7: 4.95 | Z7: - | AA7: -
C8: Standard Barrel | F8: 5 | G8: 10 | J8: 3 | K8: 7 | O8: =IFS(OR(G8="-",ISBLANK(G8)),"-",G8<1,"one-hit",G8<=3,60/L7,OR(G8=4,G8=7,G8=9),"manual",G8<7,2*60/L7,G8<9,3*60/L7,G8<=11,4*60/L7,G8>11,"???") -> 0.34188034 | P8: =IFS(OR(K8="-",ISBLANK(K8)),"-",K8<1,"one-hit",K8<=3,60/L7,OR(K8=4,K8=7,K8=9),"manual",K8<7,2*60/L7,K8<9,3*60/L7,K8<=11,4*60/L7,K8>11,"???") -> manual | Q8: - | R8: - | Z8: - | AA8: -
B9: Stoner LMG A1 | C9: Standard Barrel | D9: N/A | F9: 4 | G9: 8 | H9: N/A | J9: 3 | K9: 5 | L9: 698 | M9: =L9/60 -> 11.633333 | N9: =60/L9 -> 0.085959885 | O9: =IFS(OR(G9="-",ISBLANK(G9)),"-",G9<1,"one-hit",G9<=3,60/L9,OR(G9=4,G9=7,G9=9),"manual",G9<7,2*60/L9,G9<9,3*60/L9,G9<=11,4*60/L9,G9>11,"???") -> 0.25787966 | P9: =IFS(OR(K9="-",ISBLANK(K9)),"-",K9<1,"one-hit",K9<=3,60/L9,OR(K9=4,K9=7,K9=9),"manual",K9<7,2*60/L9,K9<9,3*60/L9,K9<=11,4*60/L9,K9>11,"???") -> 0.17191977 | Q9: - | R9: - | S9: 100 | Y9: 4.95 | Z9: - | AA9: -
C10: Long Barrel | F10: 3 | G10: 7 | J10: 2 | K10: 5 | O10: =60*3/L9 -> 0.25787966 | P10: =IFS(OR(K10="-",ISBLANK(K10)),"-",K10<1,"one-hit",K10<=3,60/L9,OR(K10=4,K10=7,K10=9),"manual",K10<7,2*60/L9,K10<9,3*60/L9,K10<=11,4*60/L9,K10>11,"???") -> 0.17191977 | Q10: - | R10: - | Z10: - | AA10: -
B11: MK-48 | C11: Standard Barrel | D11: N/A | F11: 4 | G11: 8 | H11: N/A | J11: 3 | K11: 6 | L11: 698 | M11: =L11/60 -> 11.633333 | N11: =60/L11 -> 0.085959885 | O11: =IFS(OR(G11="-",ISBLANK(G11)),"-",G11<1,"one-hit",G11<=3,60/L11,OR(G11=4,G11=7,G11=9),"manual",G11<7,2*60/L11,G11<9,3*60/L11,G11<=11,4*60/L11,G11>11,"???") -> 0.25787966 | P11: =IFS(OR(K11="-",ISBLANK(K11)),"-",K11<1,"one-hit",K11<=3,60/L11,OR(K11=4,K11=7,K11=9),"manual",K11<7,2*60/L11,K11<9,3*60/L11,K11<=11,4*60/L11,K11>11,"???") -> 0.17191977 | Q11: - | R11: - | S11: 100 | V11: 200 | Y11: 4.25 | Z11: - | AA11: -
C12: Long Barrel | F12: 3 | G12: 7 | J12: 3 | K12: 5 | O12: =60*3/L11 -> 0.25787966 | P12: =IFS(OR(K12="-",ISBLANK(K12)),"-",K12<1,"one-hit",K12<=3,60/L11,OR(K12=4,K12=7,K12=9),"manual",K12<7,2*60/L11,K12<9,3*60/L11,K12<=11,4*60/L11,K12>11,"???") -> 0.17191977 | Q12: - | R12: - | Z12: - | AA12: -
B13: Type 95 | C13: Short Barrel | D13: N/A | F13: 4 | G13: 9 | H13: N/A | J13: 3 | K13: 7 | L13: 636 | M13: =L13/60 -> 10.6 | N13: =60/L13 -> 0.094339623 | O13: =60*4/L13 -> 0.37735849 | P13: =IFS(OR(K13="-",ISBLANK(K13)),"-",K13<1,"one-hit",K13<=3,60/L13,OR(K13=4,K13=7,K13=9),"manual",K13<7,2*60/L13,K13<9,3*60/L13,K13<=11,4*60/L13,K13>11,"???") -> manual | Q13: - | R13: - | S13: 75 | Y13: 3.13 | Z13: - | AA13: -
C14: Standard Barrel | F14: 4 | G14: 8 | J14: 3 | K14: 6 | O14: =IFS(OR(G14="-",ISBLANK(G14)),"-",G14<1,"one-hit",G14<=3,60/L13,OR(G14=4,G14=7,G14=9),"manual",G14<7,2*60/L13,G14<9,3*60/L13,G14<=11,4*60/L13,G14>11,"???") -> 0.28301887 | P14: =IFS(OR(K14="-",ISBLANK(K14)),"-",K14<1,"one-hit",K14<=3,60/L13,OR(K14=4,K14=7,K14=9),"manual",K14<7,2*60/L13,K14<9,3*60/L13,K14<=11,4*60/L13,K14>11,"???") -> 0.18867925 | Q14: - | R14: - | Z14: - | AA14: -
B15: 6P41 | C15: Standard Barrel | D15: N/A | F15: 3 | G15: 6 | H15: N/A | J15: 2 | K15: 5 | L15: 590 | M15: =L15/60 -> 9.8333333 | N15: =60/L15 -> 0.10169492 | O15: =IFS(OR(G15="-",ISBLANK(G15)),"-",G15<1,"one-hit",G15<=3,60/L15,OR(G15=4,G15=7,G15=9),"manual",G15<7,2*60/L15,G15<9,3*60/L15,G15<=11,4*60/L15,G15>11,"???") -> 0.20338983 | P15: =IFS(OR(K15="-",ISBLANK(K15)),"-",K15<1,"one-hit",K15<=3,60/L15,OR(K15=4,K15=7,K15=9),"manual",K15<7,2*60/L15,K15<9,3*60/L15,K15<=11,4*60/L15,K15>11,"???") -> 0.20338983 | Q15: - | R15: - | S15: 175 | Y15: 3.97 | Z15: - | AA15: -
C16: Long Barrel | F16: 3 | G16: 6 | J16: 2 | K16: 4 | O16: =IFS(OR(G16="-",ISBLANK(G16)),"-",G16<1,"one-hit",G16<=3,60/L15,OR(G16=4,G16=7,G16=9),"manual",G16<7,2*60/L15,G16<9,3*60/L15,G16<=11,4*60/L15,G16>11,"???") -> 0.20338983 | P16: =IFS(OR(K16="-",ISBLANK(K16)),"-",K16<1,"one-hit",K16<=3,60/L15,OR(K16=4,K16=7,K16=9),"manual",K16<7,2*60/L15,K16<9,3*60/L15,K16<=11,4*60/L15,K16>11,"???") -> manual | Q16: - | R16: - | Z16: - | AA16: -
B17: Mk249 | C17: Standard Barrel | D17: N/A | F17: 5 | G17: 10 | H17: N/A | J17: 3 | K17: 7 | L17: 891 | M17: =L17/60 -> 14.85 | N17: =60/L17 -> 0.067340067 | O17: =IFS(OR(G17="-",ISBLANK(G17)),"-",G17<1,"one-hit",G17<=3,60/L17,OR(G17=4,G17=7,G17=9),"manual",G17<7,2*60/L17,G17<9,3*60/L17,G17<=11,4*60/L17,G17>11,"???") -> 0.26936027 | P17: =IFS(OR(K17="-",ISBLANK(K17)),"-",K17<1,"one-hit",K17<=3,60/L17,OR(K17=4,K17=7,K17=9),"manual",K17<7,2*60/L17,K17<9,3*60/L17,K17<=11,4*60/L17,K17>11,"???") -> manual | Q17: - | R17: - | S17: 150 | Y17: 3.97 | Z17: - | AA17: -
C18: Long Barrel | F18: 4 | G18: 10 | J18: 3 | K18: 7 | O18: =IFS(OR(G18="-",ISBLANK(G18)),"-",G18<1,"one-hit",G18<=3,60/L17,OR(G18=4,G18=7,G18=9),"manual",G18<7,2*60/L17,G18<9,3*60/L17,G18<=11,4*60/L17,G18>11,"???") -> 0.26936027 | P18: =IFS(OR(K18="-",ISBLANK(K18)),"-",K18<1,"one-hit",K18<=3,60/L17,OR(K18=4,K18=7,K18=9),"manual",K18<7,2*60/L17,K18<9,3*60/L17,K18<=11,4*60/L17,K18>11,"???") -> manual | Q18: - | R18: - | Z18: - | AA18: -
B19: Other
B20: U100 | C20: Standard Barrel | D20: N/A | F20: 4? | G20: 9? | H20: N/A | J20: 3 | K20: 7 | L20: - | M20: - | N20: - | O20: =IFS(OR(G20="-",ISBLANK(G20)),"-",G20<1,"one-hit",G20<=3,60/L20,OR(G20=4,G20=7,G20=9),"manual",G20<7,2*60/L20,G20<9,3*60/L20,G20<=11,4*60/L20,G20>11,"???") -> ??? | P20: =IFS(OR(K20="-",ISBLANK(K20)),"-",K20<1,"one-hit",K20<=3,60/L20,OR(K20=4,K20=7,K20=9),"manual",K20<7,2*60/L20,K20<9,3*60/L20,K20<=11,4*60/L20,K20>11,"???") -> manual | Q20: - | R20: - | S20: 100 | Z20: - | AA20: -
C21: Long Barrel | F21: 4? | G21: 8? | J21: 3 | K21: 6 | O21: =IFS(OR(G21="-",ISBLANK(G21)),"-",G21<1,"one-hit",G21<=3,60/L20,OR(G21=4,G21=7,G21=9),"manual",G21<7,2*60/L20,G21<9,3*60/L20,G21<=11,4*60/L20,G21>11,"???") -> ??? | P21: =IFS(OR(K21="-",ISBLANK(K21)),"-",K21<1,"one-hit",K21<=3,60/L20,OR(K21=4,K21=7,K21=9),"manual",K21<7,2*60/L20,K21<9,3*60/L20,K21<=11,4*60/L20,K21>11,"???") -> #VALUE! | Q21: - | R21: - | Z21: - | AA21: -
B22: M60E4 | C22: Standard Barrel | D22: N/A | H22: N/A | J22: 2 | K22: 4 | L22: - | M22: - | N22: - | O22: =IFS(OR(G22="-",ISBLANK(G22)),"-",G22<1,"one-hit",G22<=3,60/L22,OR(G22=4,G22=7,G22=9),"manual",G22<7,2*60/L22,G22<9,3*60/L22,G22<=11,4*60/L22,G22>11,"???") -> - | P22: =IFS(OR(K22="-",ISBLANK(K22)),"-",K22<1,"one-hit",K22<=3,60/L22,OR(K22=4,K22=7,K22=9),"manual",K22<7,2*60/L22,K22<9,3*60/L22,K22<=11,4*60/L22,K22>11,"???") -> manual | Q22: - | R22: - | S22: 200 | Z22: - | AA22: -
B23: Unique Light Machine Guns
B24: Buchon Rewards
B25: El Bastón | D25: N/A | H25: N/A | J25: 2 | K25: 4 | Q25: - | R25: - | S25: 175 | Z25: - | AA25: -
B26: Llamativo | D26: N/A | H26: N/A | J26: 3 | K26: 6 | Q26: - | R26: - | S26: 150 | Z26: - | AA26: -
B27: Fallen Ghosts
B28: T95 Spectre | D28: N/A | H28: N/A | J28: 3 | K28: 7 | Q28: - | R28: - | S28: 75 | Z28: - | AA28: -
B29: Buchon Rewards
B30: 6P41 Reaver | D30: N/A | H30: N/A | J30: 2 | K30: 5 | Q30: - | R30: - | S30: 175 | Z30: - | AA30: -
B31: Mk249 America | D31: N/A | H31: N/A | J31: 3 | K31: 7 | Q31: - | R31: - | S31: 150 | Z31: - | AA31: -
B32: MK48 Wasteland | D32: N/A | H32: N/A | J32: 3 | K32: 6 | Q32: - | R32: - | S32: 200 | Z32: - | AA32: -
B33: Type 95 Initiate | D33: N/A | H33: N/A | J33: 3 | K33: 6 | Q33: - | R33: - | S33: 75 | Z33: - | AA33: -
B34: Stoner Veteran | D34: N/A | H34: N/A | J34: 3 | K34: 5 | Q34: - | R34: - | S34: 100 | Z34: - | AA34: -
B35: Unidad RPK-74 | D35: N/A | H35: N/A | J35: 2 | K35: 5 | Q35: - | R35: - | S35: 175 | Z35: - | AA35: -
B36: Veteran Bren | H36: 3 | I36: 6 | J36: 3 | K36: 7 | Q36: - | R36: - | S36: 20 | Z36: - | AA36: -

Sheet SMGs
B2: Submachine Guns | D2: Shots To Kill Target | L2: Rate of Fire | O2: TTK | Q2: T1 Damage | S2: Magazine | Y2: Reload | Z2: Aim Delay | AA2: Aim Sens.
D3: Unidad Heavy Tier 1 | H3: Unidad Heavy Non-Tier
D4: Semi-Auto | F4: Full-Auto | H4: Semi-Auto | J4: Full-Auto | L4: RPM | M4: RPS | N4: Inter. | O4: T1 | P4: No Tier | Q4: Semi | R4: Full | S4: St. | U4: Ex. | W4: La. | Y4: Base | Z4: Base | AA4: Base
D5: Head | E5: Body | F5: Head | G5: Body | H5: Head | I5: Body | J5: Head | K5: Body | Y5: 1 | Z5: 1 | AA5: 1
B6: Customizable Submachine Guns
B7: MP5 | C7: Standard Barrel | D7: 3 | E7: 7 | F7: 4 | G7: 8 | H7: 3 | I7: 7 | J7: 4 | K7: 10 | L7: 780 | M7: =L7/60 -> 13 | N7: =60/L7 -> 0.076923077 | O7: =IFS(OR(G7="-",ISBLANK(G7)),"-",G7<1,"one-hit",G7<=3,60/L7,OR(G7=4,G7=7,G7=9),"manual",G7<7,2*60/L7,G7<9,3*60/L7,G7<=11,4*60/L7,G7>11,"???") -> 0.23076923 | P7: =IFS(OR(K7="-",ISBLANK(K7)),"-",K7<1,"one-hit",K7<=3,60/L7,OR(K7=4,K7=7,K7=9),"manual",K7<7,2*60/L7,K7<9,3*60/L7,K7<=11,4*60/L7,K7>11,"???") -> 0.30769231 | Q7: - | R7: - | S7: 20 | V7: 30 | Y7: 1.72 | Z7: - | AA7: -
C8: Long Barrel | D8: 3 | E8: 6 | F8: 4 | G8: 8 | H8: 3 | I8: 7 | J8: 4 | K8: 9 | O8: =IFS(OR(G8="-",ISBLANK(G8)),"-",G8<1,"one-hit",G8<=3,60/L7,OR(G8=4,G8=7,G8=9),"manual",G8<7,2*60/L7,G8<9,3*60/L7,G8<=11,4*60/L7,G8>11,"???") -> 0.23076923 | P8: =IFS(OR(K8="-",ISBLANK(K8)),"-",K8<1,"one-hit",K8<=3,60/L7,OR(K8=4,K8=7,K8=9),"manual",K8<7,2*60/L7,K8<9,3*60/L7,K8<=11,4*60/L7,K8>11,"???") -> manual | Q8: - | R8: - | Z8: - | AA8: -
B9: SR-635 | C9: Short Barrel | D9: 2 | E9: 4 | F9: 3 | G9: 5 | H9: 2 | I9: 5 | J9: 3 | K9: 6 | L9: 590 | M9: =L9/60 -> 9.8333333 | N9: =60/L9 -> 0.10169492 | O9: =IFS(OR(G9="-",ISBLANK(G9)),"-",G9<1,"one-hit",G9<=3,60/L9,OR(G9=4,G9=7,G9=9),"manual",G9<7,2*60/L9,G9<9,3*60/L9,G9<=11,4*60/L9,G9>11,"???") -> 0.20338983 | P9: =IFS(OR(K9="-",ISBLANK(K9)),"-",K9<1,"one-hit",K9<=3,60/L9,OR(K9=4,K9=7,K9=9),"manual",K9<7,2*60/L9,K9<9,3*60/L9,K9<=11,4*60/L9,K9>11,"???") -> 0.20338983 | Q9: - | R9: - | S9: 20 | V9: 30 | Y9: 1.47 | Z9: - | AA9: -
C10: Standard Barrel | D10: 2 | E10: 4 | F10: 2 | G10: 5 | H10: 2 | I10: 5 | J10: 3 | K10: 5 | O10: =IFS(OR(G10="-",ISBLANK(G10)),"-",G10<1,"one-hit",G10<=3,60/L9,OR(G10=4,G10=7,G10=9),"manual",G10<7,2*60/L9,G10<9,3*60/L9,G10<=11,4*60/L9,G10>11,"???") -> 0.20338983 | P10: =IFS(OR(K10="-",ISBLANK(K10)),"-",K10<1,"one-hit",K10<=3,60/L9,OR(K10=4,K10=7,K10=9),"manual",K10<7,2*60/L9,K10<9,3*60/L9,K10<=11,4*60/L9,K10>11,"???") -> 0.20338983 | Q10: - | R10: - | Z10: - | AA10: -
B11: P90 | C11: Standard Barrel | D11: 3 | E11: 6 | F11: 3 | G11: 7 | H11: 3 | I11: 7 | J11: 4 | K11: 8 | L11: 878 | M11: =L11/60 -> 14.633333 | N11: =60/L11 -> 0.06833713 | O11: =60*3/L11 -> 0.20501139 | P11: =IFS(OR(K11="-",ISBLANK(K11)),"-",K11<1,"one-hit",K11<=3,60/L11,OR(K11=4,K11=7,K11=9),"manual",K11<7,2*60/L11,K11<9,3*60/L11,K11<=11,4*60/L11,K11>11,"???") -> 0.20501139 | Q11: - | R11: - | S11: 50 | Y11: 2.27 | Z11: - | AA11: -
C12: Long Barrel | D12: 3 | E12: 5 | F12: 3 | G12: 6 | H12: 3 | I12: 6 | J12: 3 | K12: 7 | O12: =IFS(OR(G12="-",ISBLANK(G12)),"-",G12<1,"one-hit",G12<=3,60/L11,OR(G12=4,G12=7,G12=9),"manual",G12<7,2*60/L11,G12<9,3*60/L11,G12<=11,4*60/L11,G12>11,"???") -> 0.13667426 | P12: =IFS(OR(K12="-",ISBLANK(K12)),"-",K12<1,"one-hit",K12<=3,60/L11,OR(K12=4,K12=7,K12=9),"manual",K12<7,2*60/L11,K12<9,3*60/L11,K12<=11,4*60/L11,K12>11,"???") -> manual | Q12: - | R12: - | Z12: - | AA12: -
B13: PP19 | C13: Standard Barrel | D13: 3 | E13: 6 | F13: 3 | G13: 7 | H13: 3 | I13: 7 | J13: 4 | K13: 8 | L13: 685 | M13: =L13/60 -> 11.416667 | N13: =60/L13 -> 0.087591241 | O13: =60*3/L13 -> 0.26277372 | P13: =IFS(OR(K13="-",ISBLANK(K13)),"-",K13<1,"one-hit",K13<=3,60/L13,OR(K13=4,K13=7,K13=9),"manual",K13<7,2*60/L13,K13<9,3*60/L13,K13<=11,4*60/L13,K13>11,"???") -> 0.26277372 | Q13: - | R13: - | S13: 64 | Y13: 2.27 | Z13: - | AA13: -
C14: Long Barrel | D14: 3 | E14: 5 | F14: 3 | G14: 6 | H14: 3 | I14: 6 | J14: 3 | K14: 7 | O14: =IFS(OR(G14="-",ISBLANK(G14)),"-",G14<1,"one-hit",G14<=3,60/L13,OR(G14=4,G14=7,G14=9),"manual",G14<7,2*60/L13,G14<9,3*60/L13,G14<=11,4*60/L13,G14>11,"???") -> 0.17518248 | P14: =IFS(OR(K14="-",ISBLANK(K14)),"-",K14<1,"one-hit",K14<=3,60/L13,OR(K14=4,K14=7,K14=9),"manual",K14<7,2*60/L13,K14<9,3*60/L13,K14<=11,4*60/L13,K14>11,"???") -> manual | Q14: - | R14: - | Z14: - | AA14: -
B15: MP7 | C15: Standard Barrel | D15: 3 | E15: 7 | F15: 4 | G15: 9 | H15: 4 | I15: 8 | J15: 5 | K15: 10 | L15: 923 | M15: =L15/60 -> 15.383333 | N15: =60/L15 -> 0.065005417 | O15: =60*3/L15 -> 0.19501625 | P15: =IFS(OR(K15="-",ISBLANK(K15)),"-",K15<1,"one-hit",K15<=3,60/L15,OR(K15=4,K15=7,K15=9),"manual",K15<7,2*60/L15,K15<9,3*60/L15,K15<=11,4*60/L15,K15>11,"???") -> 0.26002167 | Q15: - | R15: - | S15: 20 | V15: 30 | Y15: 1.97 | Z15: - | AA15: -
C16: Long Barrel | D16: 3 | E16: 7 | F16: 4 | G16: 8 | H16: 3 | I16: 7 | J16: 4 | K16: 10 | O16: =IFS(OR(G16="-",ISBLANK(G16)),"-",G16<1,"one-hit",G16<=3,60/L15,OR(G16=4,G16=7,G16=9),"manual",G16<7,2*60/L15,G16<9,3*60/L15,G16<=11,4*60/L15,G16>11,"???") -> 0.19501625 | P16: =IFS(OR(K16="-",ISBLANK(K16)),"-",K16<1,"one-hit",K16<=3,60/L15,OR(K16=4,K16=7,K16=9),"manual",K16<7,2*60/L15,K16<9,3*60/L15,K16<=11,4*60/L15,K16>11,"???") -> 0.26002167 | Q16: - | R16: - | Z16: - | AA16: -
B17: MPX | C17: Standard Barrel | D17: 3 | E17: 6 | F17: 3 | G17: 7 | H17: 3 | I17: 7 | J17: 4 | K17: 8 | L17: 828 | M17: =L17/60 -> 13.8 | N17: =60/L17 -> 0.072463768 | O17: =60*3/L17 -> 0.2173913 | P17: =IFS(OR(K17="-",ISBLANK(K17)),"-",K17<1,"one-hit",K17<=3,60/L17,OR(K17=4,K17=7,K17=9),"manual",K17<7,2*60/L17,K17<9,3*60/L17,K17<=11,4*60/L17,K17>11,"???") -> 0.2173913 | Q17: - | R17: - | S17: 20 | V17: 30 | Y17: 1.97 | Z17: - | AA17: -
C18: Long Barrel | D18: 3 | E18: 6 | F18: 3 | G18: 7 | H18: 3 | I18: 6 | J18: 3 | K18: 7 | O18: =60*3/L17 -> 0.2173913 | P18: =IFS(OR(K18="-",ISBLANK(K18)),"-",K18<1,"one-hit",K18<=3,60/L17,OR(K18=4,K18=7,K18=9),"manual",K18<7,2*60/L17,K18<9,3*60/L17,K18<=11,4*60/L17,K18>11,"???") -> manual | Q18: - | R18: - | Z18: - | AA18: -
B19: PSG | C19: Standard Barrel | D19: 3 | E19: 6 | F19: 3 | G19: 7 | H19: 3 | I19: 6 | J19: 4 | K19: 8 | L19: 780 | M19: =L19/60 -> 13 | N19: =60/L19 -> 0.076923077 | O19: =60*3/L19 -> 0.23076923 | P19: =IFS(OR(K19="-",ISBLANK(K19)),"-",K19<1,"one-hit",K19<=3,60/L19,OR(K19=4,K19=7,K19=9),"manual",K19<7,2*60/L19,K19<9,3*60/L19,K19<=11,4*60/L19,K19>11,"???") -> 0.23076923 | Q19: - | R19: - | S19: 20 | V19: 30 | Y19: 2.27 | Z19: - | AA19: -
C20: Long Barrel | D20: 3 | E20: 5 | F20: 3 | G20: 6 | H20: 3 | I20: 6 | J20: 3 | K20: 7 | O20: =IFS(OR(G20="-",ISBLANK(G20)),"-",G20<1,"one-hit",G20<=3,60/L19,OR(G20=4,G20=7,G20=9),"manual",G20<7,2*60/L19,G20<9,3*60/L19,G20<=11,4*60/L19,G20>11,"???") -> 0.15384615 | P20: =IFS(OR(K20="-",ISBLANK(K20)),"-",K20<1,"one-hit",K20<=3,60/L19,OR(K20=4,K20=7,K20=9),"manual",K20<7,2*60/L19,K20<9,3*60/L19,K20<=11,4*60/L19,K20>11,"???") -> manual | Q20: - | R20: - | Z20: - | AA20: -
B21: 9mm C1 | C21: Standard Barrel | D21: N/A | F21: 2 | G21: 4 | H21: N/A | J21: 2 | K21: 5 | L21: 538 | M21: =L21/60 -> 8.9666667 | N21: =60/L21 -> 0.11152416 | O21: =60*2/L21 -> 0.22304833 | P21: =IFS(OR(K21="-",ISBLANK(K21)),"-",K21<1,"one-hit",K21<=3,60/L21,OR(K21=4,K21=7,K21=9),"manual",K21<7,2*60/L21,K21<9,3*60/L21,K21<=11,4*60/L21,K21>11,"???") -> 0.22304833 | Q21: - | R21: - | S21: 34 | Y21: 2.27 | Z21: - | AA21: -
C22: Long Barrel | F22: 2 | G22: 4 | J22: 2 | K22: 5 | O22: =60*2/L21 -> 0.22304833 | P22: =IFS(OR(K22="-",ISBLANK(K22)),"-",K22<1,"one-hit",K22<=3,60/L21,OR(K22=4,K22=7,K22=9),"manual",K22<7,2*60/L21,K22<9,3*60/L21,K22<=11,4*60/L21,K22>11,"???") -> 0.22304833 | Q22: - | R22: - | Z22: - | AA22: -
B23: 9x19VSN | C23: Standard Barrel | D23: 2 | E23: 5 | F23: 3 | G23: 6 | H23: 3 | I23: 6 | J23: 3 | K23: 7 | L23: 682 | M23: =L23/60 -> 11.366667 | N23: =60/L23 -> 0.08797654 | O23: =IFS(OR(G23="-",ISBLANK(G23)),"-",G23<1,"one-hit",G23<=3,60/L23,OR(G23=4,G23=7,G23=9),"manual",G23<7,2*60/L23,G23<9,3*60/L23,G23<=11,4*60/L23,G23>11,"???") -> 0.17595308 | P23: =IFS(OR(K23="-",ISBLANK(K23)),"-",K23<1,"one-hit",K23<=3,60/L23,OR(K23=4,K23=7,K23=9),"manual",K23<7,2*60/L23,K23<9,3*60/L23,K23<=11,4*60/L23,K23>11,"???") -> manual | Q23: - | R23: - | S23: 20 | V23: 30 | Y23: 2.48 | Z23: - | AA23: -
C24: Long Barrel | D24: 2 | E24: 5 | F24: 3 | G24: 6 | H24: 3 | I24: 5 | J24: 3 | K24: 7 | O24: =IFS(OR(G24="-",ISBLANK(G24)),"-",G24<1,"one-hit",G24<=3,60/L23,OR(G24=4,G24=7,G24=9),"manual",G24<7,2*60/L23,G24<9,3*60/L23,G24<=11,4*60/L23,G24>11,"???") -> 0.17595308 | P24: =IFS(OR(K24="-",ISBLANK(K24)),"-",K24<1,"one-hit",K24<=3,60/L23,OR(K24=4,K24=7,K24=9),"manual",K24<7,2*60/L23,K24<9,3*60/L23,K24<=11,4*60/L23,K24>11,"???") -> manual | Q24: - | R24: - | Z24: - | AA24: -
B25: Scorpion EVO 3 | C25: Standard Barrel | D25: 4 | E25: 8 | F25: 5 | G25: 10 | H25: 4 | I25: 10 | J25: 5 | K25: 12 | L25: 1111 | M25: =L25/60 -> 18.516667 | N25: =60/L25 -> 0.054005401 | O25: =IFS(OR(G25="-",ISBLANK(G25)),"-",G25<1,"one-hit",G25<=3,60/L25,OR(G25=4,G25=7,G25=9),"manual",G25<7,2*60/L25,G25<9,3*60/L25,G25<=11,4*60/L25,G25>11,"???") -> 0.2160216 | P25: =IFS(OR(K25="-",ISBLANK(K25)),"-",K25<1,"one-hit",K25<=3,60/L25,OR(K25=4,K25=7,K25=9),"manual",K25<7,2*60/L25,K25<9,3*60/L25,K25<=11,4*60/L25,K25>11,"???") -> ??? | Q25: - | R25: - | S25: 20 | V25: 30 | Y25: 1.58 | Z25: - | AA25: -
C26: Long Barrel | D26: 3 | E26: 7 | F26: 4 | G26: 9 | H26: 4 | I26: 9 | J26: 5 | K26: 10 | O26: =60*4/L25 -> 0.2160216 | P26: =IFS(OR(K26="-",ISBLANK(K26)),"-",K26<1,"one-hit",K26<=3,60/L25,OR(K26=4,K26=7,K26=9),"manual",K26<7,2*60/L25,K26<9,3*60/L25,K26<=11,4*60/L25,K26>11,"???") -> 0.2160216 | Q26: - | R26: - | Z26: - | AA26: -
B27: Vector .45 ACP | C27: Short Barrel | D27: 4 | E27: 8 | F27: 5 | G27: 10 | H27: 4 | I27: 9 | J27: 5 | K27: 12 | L27: 1137 | M27: =L27/60 -> 18.95 | N27: =60/L27 -> 0.052770449 | O27: =IFS(OR(G27="-",ISBLANK(G27)),"-",G27<1,"one-hit",G27<=3,60/L27,OR(G27=4,G27=7,G27=9),"manual",G27<7,2*60/L27,G27<9,3*60/L27,G27<=11,4*60/L27,G27>11,"???") -> 0.21108179 | P27: =IFS(OR(K27="-",ISBLANK(K27)),"-",K27<1,"one-hit",K27<=3,60/L27,OR(K27=4,K27=7,K27=9),"manual",K27<7,2*60/L27,K27<9,3*60/L27,K27<=11,4*60/L27,K27>11,"???") -> ??? | Q27: - | R27: - | S27: 20 | V27: 30 | Y27: 1.67 | Z27: - | AA27: -
C28: Standard Barrel | D28: 3 | E28: 7 | F28: 4 | G28: 9 | H28: 4 | I28: 8 | J28: 5 | K28: 10 | O28: =60*4/L27 -> 0.21108179 | P28: =IFS(OR(K28="-",ISBLANK(K28)),"-",K28<1,"one-hit",K28<=3,60/L27,OR(K28=4,K28=7,K28=9),"manual",K28<7,2*60/L27,K28<9,3*60/L27,K28<=11,4*60/L27,K28>11,"???") -> 0.21108179 | Q28: - | R28: - | Z28: - | AA28: -
B29: Fallen Ghosts
B30: PDR | C30: Short Barrel | D30: 3 | E30: 7 | F30: 4 | G30: 8 | H30: 4 | I30: 8 | J30: 4 | K30: 10 | L30: 730 | M30: =L30/60 -> 12.166667 | N30: =60/L30 -> 0.082191781 | O30: =IFS(OR(G30="-",ISBLANK(G30)),"-",G30<1,"one-hit",G30<=3,60/L30,OR(G30=4,G30=7,G30=9),"manual",G30<7,2*60/L30,G30<9,3*60/L30,G30<=11,4*60/L30,G30>11,"???") -> 0.24657534 | P30: =IFS(OR(K30="-",ISBLANK(K30)),"-",K30<1,"one-hit",K30<=3,60/L30,OR(K30=4,K30=7,K30=9),"manual",K30<7,2*60/L30,K30<9,3*60/L30,K30<=11,4*60/L30,K30>11,"???") -> 0.32876712 | Q30: - | R30: - | S30: 20 | V30: 30 | Y30: 1.47 | Z30: - | AA30: -
C31: Standard Barrel | D31: 3 | E31: 6 | F31: 4 | G31: 8 | H31: 3 | I31: 7 | J31: 4 | K31: 9 | O31: =IFS(OR(G31="-",ISBLANK(G31)),"-",G31<1,"one-hit",G31<=3,60/L30,OR(G31=4,G31=7,G31=9),"manual",G31<7,2*60/L30,G31<9,3*60/L30,G31<=11,4*60/L30,G31>11,"???") -> 0.24657534 | P31: =IFS(OR(K31="-",ISBLANK(K31)),"-",K31<1,"one-hit",K31<=3,60/L30,OR(K31=4,K31=7,K31=9),"manual",K31<7,2*60/L30,K31<9,3*60/L30,K31<=11,4*60/L30,K31>11,"???") -> manual | Q31: - | R31: - | Z31: - | AA31: -
B32: Unique Submachine Guns
B33: Buchon Rewards
B34: ¡UY! | H34: 2 | I34: 5 | J34: 3 | K34: 6 | Q34: - | R34: - | S34: 20 | Z34: - | AA34: -
B35: Experimento #42 | D35: N/A | H35: N/A | J35: 2 | K35: 5 | Q35: - | R35: - | S35: 34 | Z35: - | AA35: -
B36: Mendeleyev | D36: N/A | H36: N/A | J36: 4 | K36: 8 | Q36: - | R36: - | S36: 25 | Z36: - | AA36: -
B37: Residuos | H37: 3 | I37: 6 | J37: 3 | K37: 7 | Q37: - | R37: - | S37: 64 | Z37: - | AA37: -
B38: Fallen Ghosts
B39: Extranjeros PDR | H39: 2 | I39: 5 | J39: 2 | K39: 5 | Q39: - | R39: - | S39: 30 | Z39: - | AA39: -
B40: SR635 Apparition | H40: 2 | I40: 5 | J40: 3 | K40: 6 | Q40: - | R40: - | S40: 30 | Z40: - | AA40: -
B41: Ubisoft Club Rewards
...

Sheet Shotguns
B2: Shotguns | D2: Shots To Kill Target | L2: Rate of Fire | O2: TTK | Q2: T1 Damage | S2: Magazine | Y2: Reload | Z2: Aim Delay | AA2: Aim Sens.
D3: Unidad Heavy Tier 1 | H3: Unidad Heavy Non-Tier
D4: Semi-Auto | F4: Full-Auto | H4: Semi-Auto | J4: Full-Auto | L4: RPM | M4: RPS | N4: Inter. | O4: T1 | P4: No Tier | Q4: Semi | R4: Full | S4: St. | U4: Ex. | W4: La. | Y4: Base | Z4: Base | AA4: Base
D5: Head | E5: Body | F5: Head | G5: Body | H5: Head | I5: Body | J5: Head | K5: Body | Y5: 1 | Z5: 1 | AA5: 1
B6: Customizable Shotguns
B7: Super Shorty | C7: Standard Barrel | D7: 1 | E7: 1 | F7: N/A | H7: 1 | I7: 1 | J7: N/A | O7: one-hit | P7: one-hit | Q7: - | R7: - | S7: 2 | Z7: - | AA7: -
C8: Long Barrel | D8: 1 | E8: 1 | H8: 1 | I8: 1 | O8: one-hit | P8: one-hit | Q8: - | R8: - | Z8: - | AA8: -
B9: SASG-12 | C9: Standard Barrel | D9: 1 | E9: 2 | F9: 1 | G9: 3 | H9: 1 | I9: 2 | J9: 1 | K9: 2 | L9: 300 | M9: =L9/60 -> 5 | N9: =60/L9 -> 0.2 | O9: =IFS(OR(G9="-",ISBLANK(G9)),"-",G9<1,"one-hit",G9<=3,60/L9,OR(G9=4,G9=7,G9=9),"manual",G9<7,2*60/L9,G9<9,3*60/L9,G9<=11,4*60/L9,G9>11,"???") -> 0.2 | P9: =IFS(OR(K9="-",ISBLANK(K9)),"-",K9<1,"one-hit",K9<=3,60/L9,OR(K9=4,K9=7,K9=9),"manual",K9<7,2*60/L9,K9<9,3*60/L9,K9<=11,4*60/L9,K9>11,"???") -> 0.2 | Q9: - | R9: - | S9: 5 | U9: 10 | W9: 30 | Z9: - | AA9: -
C10: Long Barrel | D10: 1 | E10: 2 | F10: 2 | G10: 3 | H10: 1 | I10: 2 | J10: 1 | K10: 2 | O10: =IFS(OR(G10="-",ISBLANK(G10)),"-",G10<1,"one-hit",G10<=3,60/L9,OR(G10=4,G10=7,G10=9),"manual",G10<7,2*60/L9,G10<9,3*60/L9,G10<=11,4*60/L9,G10>11,"???") -> 0.2 | P10: =IFS(OR(K10="-",ISBLANK(K10)),"-",K10<1,"one-hit",K10<=3,60/L9,OR(K10=4,K10=7,K10=9),"manual",K10<7,2*60/L9,K10<9,3*60/L9,K10<=11,4*60/L9,K10>11,"???") -> 0.2 | Q10: - | R10: - | Z10: - | AA10: -
B11: SPAS-12 | C11: Short Barrel | D11: 1 | E11: 2 | F11: N/A | H11: 1 | I11: 1 | J11: N/A | O11: =IFS(OR(G11="-",ISBLANK(G11)),"-",G11<1,"one-hit",G11<=3,60/L11,OR(G11=4,G11=7,G11=9),"manual",G11<7,2*60/L11,G11<9,3*60/L11,G11<=11,4*60/L11,G11>11,"???") -> - | P11: one-hit | Q11: - | R11: - | S11: 5 | V11: 8 | Z11: - | AA11: -
C12: Standard Barrel | D12: 1 | E12: 2 | H12: 1 | I12: 1 | O12: =IFS(OR(G12="-",ISBLANK(G12)),"-",G12<1,"one-hit",G12<=3,60/L11,OR(G12=4,G12=7,G12=9),"manual",G12<7,2*60/L11,G12<9,3*60/L11,G12<=11,4*60/L11,G12>11,"???") -> - | P12: one-hit | Q12: - | R12: - | Z12: - | AA12: -
C13: Long Barrel | D13: 1 | E13: 2 | H13: 1 | I13: 1 | O13: =IFS(OR(G13="-",ISBLANK(G13)),"-",G13<1,"one-hit",G13<=3,60/L11,OR(G13=4,G13=7,G13=9),"manual",G13<7,2*60/L11,G13<9,3*60/L11,G13<=11,4*60/L11,G13>11,"???") -> - | P13: one-hit | Q13: - | R13: - | Z13: - | AA13: -
B14: Other
B15: M4 Super 90 | C15: Standard Barrel | D15: - | E15: - | F15: N/A | H15: - | I15: - | J15: N/A | O15: =IFS(OR(G15="-",ISBLANK(G15)),"-",G15<1,"one-hit",G15<=3,60/L15,OR(G15=4,G15=7,G15=9),"manual",G15<7,2*60/L15,G15<9,3*60/L15,G15<=11,4*60/L15,G15>11,"???") -> - | P15: =IFS(OR(K15="-",ISBLANK(K15)),"-",K15<1,"one-hit",K15<=3,60/L15,OR(K15=4,K15=7,K15=9),"manual",K15<7,2*60/L15,K15<9,3*60/L15,K15<=11,4*60/L15,K15>11,"???") -> - | Q15: - | R15: - | S15: 5 | V15: 8 | Z15: - | AA15: -
C16: Long Barrel | D16: - | E16: - | H16: - | I16: - | O16: =IFS(OR(G16="-",ISBLANK(G16)),"-",G16<1,"one-hit",G16<=3,60/L15,OR(G16=4,G16=7,G16=9),"manual",G16<7,2*60/L15,G16<9,3*60/L15,G16<=11,4*60/L15,G16>11,"???") -> - | P16: =IFS(OR(K16="-",ISBLANK(K16)),"-",K16<1,"one-hit",K16<=3,60/L15,OR(K16=4,K16=7,K16=9),"manual",K16<7,2*60/L15,K16<9,3*60/L15,K16<=11,4*60/L15,K16>11,"???") -> - | Q16: - | R16: - | Z16: - | AA16: -
B17: Unique Shotguns
B18: Buchon Rewards
B19: ¡SILENCIO! | D19: 1 | E19: 2 | F19: 1 | G19: 2 | H19: 1 | I19: 2 | J19: 1 | K19: 2 | L19: - | M19: - | N19: - | O19: =IFS(OR(G19="-",ISBLANK(G19)),"-",G19<1,"one-hit",G19<=3,60/L19,OR(G19=4,G19=7,G19=9),"manual",G19<7,2*60/L19,G19<9,3*60/L19,G19<=11,4*60/L19,G19>11,"???") -> #VALUE! | P19: one-hit | Q19: - | R19: - | S19: 30 | Y19: - | Z19: - | AA19: -
B20: El Cuentista | D20: 1 | E20: 1 | F20: N/A | H20: 1 | I20: 1 | J20: N/A | L20: - | M20: - | N20: - | O20: =IFS(OR(G20="-",ISBLANK(G20)),"-",G20<1,"one-hit",G20<=3,60/L20,OR(G20=4,G20=7,G20=9),"manual",G20<7,2*60/L20,G20<9,3*60/L20,G20<=11,4*60/L20,G20>11,"???") -> - | P20: one-hit | Q20: - | R20: - | S20: 2 | Y20: - | Z20: - | AA20: -
B21: El Obsequio | D21: 1 | E21: 1 | F21: N/A | H21: 1 | I21: 1 | J21: N/A | L21: - | M21: - | N21: - | O21: =IFS(OR(G21="-",ISBLANK(G21)),"-",G21<1,"one-hit",G21<=3,60/L21,OR(G21=4,G21=7,G21=9),"manual",G21<7,2*60/L21,G21<9,3*60/L21,G21<=11,4*60/L21,G21>11,"???") -> - | P21: one-hit | Q21: - | R21: - | S21: 5 | Y21: - | Z21: - | AA21: -
B22: Other
B23: Ice Shard | D23: 1 | E23: 2 | F23: N/A | H23: 1 | I23: 1 | J23: N/A | L23: - | M23: - | N23: - | O23: =IFS(OR(G23="-",ISBLANK(G23)),"-",G23<1,"one-hit",G23<=3,60/L23,OR(G23=4,G23=7,G23=9),"manual",G23<7,2*60/L23,G23<9,3*60/L23,G23<=11,4*60/L23,G23>11,"???") -> - | P23: one-hit | Q23: - | R23: - | S23: 2 | Y23: - | Z23: - | AA23: -
B24: RevSG-12 | D24: - | E24: - | F24: - | G24: - | H24: - | I24: - | J24: - | K24: - | L24: - | M24: - | N24: - | O24: =IFS(OR(G24="-",ISBLANK(G24)),"-",G24<1,"one-hit",G24<=3,60/L24,OR(G24=4,G24=7,G24=9),"manual",G24<7,2*60/L24,G24<9,3*60/L24,G24<=11,4*60/L24,G24>11,"???") -> - | P24: one-hit | Q24: - | R24: - | S24: 6 | Y24: - | Z24: - | AA24: -
B25: SASG-12 Frontier | D25: 1 | E25: 2 | F25: 1 | G25: 2 | H25: 1 | I25: 2 | J25: 1 | K25: 2 | L25: - | M25: - | N25: - | O25: =IFS(OR(G25="-",ISBLANK(G25)),"-",G25<1,"one-hit",G25<=3,60/L25,OR(G25=4,G25=7,G25=9),"manual",G25<7,2*60/L25,G25<9,3*60/L25,G25<=11,4*60/L25,G25>11,"???") -> #VALUE! | P25: one-hit | Q25: - | R25: - | S25: 10 | Y25: - | Z25: - | AA25: -
B26: SPAS-12 Secutor | D26: 1 | E26: 1 | F26: N/A | H26: 1 | I26: 1 | J26: N/A | L26: - | M26: - | N26: - | O26: =IFS(OR(G26="-",ISBLANK(G26)),"-",G26<1,"one-hit",G26<=3,60/L26,OR(G26=4,G26=7,G26=9),"manual",G26<7,2*60/L26,G26<9,3*60/L26,G26<=11,4*60/L26,G26>11,"???") -> - | P26: one-hit | Q26: - | R26: - | S26: 5 | Y26: - | Z26: - | AA26: -
B27: SPAS 12 Skulls and Blood | D27: 1 | E27: 1 | F27: N/A | H27: 1 | I27: 1 | J27: N/A | L27: - | M27: - | N27: - | O27: =IFS(OR(G27="-",ISBLANK(G27)),"-",G27<1,"one-hit",G27<=3,60/L27,OR(G27=4,G27=7,G27=9),"manual",G27<7,2*60/L27,G27<9,3*60/L27,G27<=11,4*60/L27,G27>11,"???") -> - | P27: one-hit | Q27: - | R27: - | S27: 5 | Y27: - | Z27: - | AA27: -
B28: Super Shorty Legacy | D28: 1 | E28: 1 | F28: N/A | H28: 1 | I28: 1 | J28: N/A | L28: - | M28: - | N28: - | O28: =IFS(OR(G28="-",ISBLANK(G28)),"-",G28<1,"one-hit",G28<=3,60/L28,OR(G28=4,G28=7,G28=9),"manual",G28<7,2*60/L28,G28<9,3*60/L28,G28<=11,4*60/L28,G28>11,"???") -> - | P28: one-hit | Q28: - | R28: - | S28: 2 | Y28: - | Z28: - | AA28: -
B29: Wilderness | D29: 1 | E29: 2 | F29: N/A | H29: 1 | I29: 1 | J29: N/A | L29: - | M29: - | N29: - | O29: =IFS(OR(G29="-",ISBLANK(G29)),"-",G29<1,"one-hit",G29<=3,60/L29,OR(G29=4,G29=7,G29=9),"manual",G29<7,2*60/L29,G29<9,3*60/L29,G29<=11,4*60/L29,G29>11,"???") -> - | P29: one-hit | Q29: - | R29: - | S29: 2 | Y29: - | Z29: - | AA29: -

Sheet Sidearms
B2: Sidearms | D2: Shots To Kill Target | L2: Rate of Fire | O2: TTK | Q2: T1 Damage | S2: Magazine | Y2: Reload | Z2: Aim Delay | AA2: Aim Sens.
D3: Unidad Heavy Tier 1 | H3: Unidad Heavy Non-Tier
D4: Semi-Auto | F4: Full-Auto | H4: Semi-Auto | J4: Full-Auto | L4: RPM | M4: RPS | N4: Inter. | O4: T1 | P4: No Tier | Q4: Semi | R4: Full | S4: St. | U4: Ex. | W4: La. | Y4: Base | Z4: Base | AA4: Base
D5: Head | E5: Body | F5: Head | G5: Body | H5: Head | I5: Body | J5: Head | K5: Body | Y5: 1 | Z5: 1 | AA5: 1
B6: Customizable Sidearms
B7: Handguns
B8: P45T | D8: 5 | E8: 11 | F8: N/A | H8: 4 | I8: 8 | J8: N/A | O8: =IFS(OR(G8="-",ISBLANK(G8)),"-",G8<1,"one-hit",G8<=3,60/L8,OR(G8=4,G8=7,G8=9),"manual",G8<7,2*60/L8,G8<9,3*60/L8,G8<=11,4*60/L8,G8>11,"???") -> - | P8: =IFS(OR(K8="-",ISBLANK(K8)),"-",K8<1,"one-hit",K8<=3,60/L8,OR(K8=4,K8=7,K8=9),"manual",K8<7,2*60/L8,K8<9,3*60/L8,K8<=11,4*60/L8,K8>11,"???") -> - | Q8: - | R8: - | S8: 15 | V8: 20 | Y8: 1.32 | Z8: - | AA8: -
B9: 5.7 USG | D9: 5 | E9: 10 | F9: N/A | H9: 3 | I9: 7 | J9: N/A | O9: =IFS(OR(G9="-",ISBLANK(G9)),"-",G9<1,"one-hit",G9<=3,60/L9,OR(G9=4,G9=7,G9=9),"manual",G9<7,2*60/L9,G9<9,3*60/L9,G9<=11,4*60/L9,G9>11,"???") -> - | P9: =IFS(OR(K9="-",ISBLANK(K9)),"-",K9<1,"one-hit",K9<=3,60/L9,OR(K9=4,K9=7,K9=9),"manual",K9<7,2*60/L9,K9<9,3*60/L9,K9<=11,4*60/L9,K9>11,"???") -> - | Q9: - | R9: - | S9: 20 | V9: 30 | Y9: 1.22 | Z9: - | AA9: -
B10: M1911 | D10: 5 | E10: 11 | F10: N/A | H10: 3 | I10: 7 | J10: N/A | O10: =IFS(OR(G10="-",ISBLANK(G10)),"-",G10<1,"one-hit",G10<=3,60/L10,OR(G10=4,G10=7,G10=9),"manual",G10<7,2*60/L10,G10<9,3*60/L10,G10<=11,4*60/L10,G10>11,"???") -> - | P10: =IFS(OR(K10="-",ISBLANK(K10)),"-",K10<1,"one-hit",K10<=3,60/L10,OR(K10=4,K10=7,K10=9),"manual",K10<7,2*60/L10,K10<9,3*60/L10,K10<=11,4*60/L10,K10>11,"???") -> - | Q10: - | R10: - | S10: 8 | V10: 15 | Y10: 1.42 | Z10: - | AA10: -
B11: P12 | D11: 5 | E11: 10 | F11: N/A | H11: 3 | I11: 7 | J11: N/A | O11: =IFS(OR(G11="-",ISBLANK(G11)),"-",G11<1,"one-hit",G11<=3,60/L11,OR(G11=4,G11=7,G11=9),"manual",G11<7,2*60/L11,G11<9,3*60/L11,G11<=11,4*60/L11,G11>11,"???") -> - | P11: =IFS(OR(K11="-",ISBLANK(K11)),"-",K11<1,"one-hit",K11<=3,60/L11,OR(K11=4,K11=7,K11=9),"manual",K11<7,2*60/L11,K11<9,3*60/L11,K11<=11,4*60/L11,K11>11,"???") -> - | Q11: - | R11: - | S11: 12 | V11: 20 | Y11: 1.27 | Z11: - | AA11: -
B12: P227 | D12: 4 | E12: 10 | F12: N/A | H12: 3 | I12: 7 | J12: N/A | O12: =IFS(OR(G12="-",ISBLANK(G12)),"-",G12<1,"one-hit",G12<=3,60/L12,OR(G12=4,G12=7,G12=9),"manual",G12<7,2*60/L12,G12<9,3*60/L12,G12<=11,4*60/L12,G12>11,"???") -> - | P12: =IFS(OR(K12="-",ISBLANK(K12)),"-",K12<1,"one-hit",K12<=3,60/L12,OR(K12=4,K12=7,K12=9),"manual",K12<7,2*60/L12,K12<9,3*60/L12,K12<=11,4*60/L12,K12>11,"???") -> - | Q12: - | R12: - | S12: 10 | V12: 15 | Y12: 1.32 | Z12: - | AA12: -
B13: M9 | D13: 4 | E13: 9 | F13: N/A | H13: 3 | I13: 7 | J13: N/A | O13: =IFS(OR(G13="-",ISBLANK(G13)),"-",G13<1,"one-hit",G13<=3,60/L13,OR(G13=4,G13=7,G13=9),"manual",G13<7,2*60/L13,G13<9,3*60/L13,G13<=11,4*60/L13,G13>11,"???") -> - | P13: =IFS(OR(K13="-",ISBLANK(K13)),"-",K13<1,"one-hit",K13<=3,60/L13,OR(K13=4,K13=7,K13=9),"manual",K13<7,2*60/L13,K13<9,3*60/L13,K13<=11,4*60/L13,K13>11,"???") -> - | Q13: - | R13: - | S13: 15 | V13: 25 | Y13: 1.37 | Z13: - | AA13: -
B14: D-50 | D14: 2 | E14: 4 | F14: N/A | H14: 2 | I14: 3 | J14: N/A | O14: =IFS(OR(G14="-",ISBLANK(G14)),"-",G14<1,"one-hit",G14<=3,60/L14,OR(G14=4,G14=7,G14=9),"manual",G14<7,2*60/L14,G14<9,3*60/L14,G14<=11,4*60/L14,G14>11,"???") -> - | P14: =IFS(OR(K14="-",ISBLANK(K14)),"-",K14<1,"one-hit",K14<=3,60/L14,OR(K14=4,K14=7,K14=9),"manual",K14<7,2*60/L14,K14<9,3*60/L14,K14<=11,4*60/L14,K14>11,"???") -> - | Q14: - | R14: - | S14: 7 | Y14: 1.93 | Z14: - | AA14: -
B15: Compact Machine Guns
B16: SMG-11 | D16: N/A | F16: 8 | G16: 19 | H16: N/A | J16: 10 | K16: 21 | L16: 1160 | M16: =L16/60 -> 19.333333 | N16: =60/L16 -> 0.051724138 | O16: =IFS(OR(G16="-",ISBLANK(G16)),"-",G16<1,"one-hit",G16<=3,60/L16,OR(G16=4,G16=7,G16=9),"manual",G16<7,2*60/L16,G16<9,3*60/L16,G16<=11,4*60/L16,G16>11,"???") -> ??? | P16: =IFS(OR(K16="-",ISBLANK(K16)),"-",K16<1,"one-hit",K16<=3,60/L16,OR(K16=4,K16=7,K16=9),"manual",K16<7,2*60/L16,K16<9,3*60/L16,K16<=11,4*60/L16,K16>11,"???") -> ??? | Q16: - | R16: - | S16: 20 | Y16: 1.97 | Z16: - | AA16: -
B17: Skorpion | D17: N/A | F17: 6 | G17: 14 | H17: N/A | J17: 7 | K17: 15 | L17: 885 | M17: =L17/60 -> 14.75 | N17: =60/L17 -> 0.06779661 | O17: =IFS(OR(G17="-",ISBLANK(G17)),"-",G17<1,"one-hit",G17<=3,60/L17,OR(G17=4,G17=7,G17=9),"manual",G17<7,2*60/L17,G17<9,3*60/L17,G17<=11,4*60/L17,G17>11,"???") -> ??? | P17: =IFS(OR(K17="-",ISBLANK(K17)),"-",K17<1,"one-hit",K17<=3,60/L17,OR(K17=4,K17=7,K17=9),"manual",K17<7,2*60/L17,K17<9,3*60/L17,K17<=11,4*60/L17,K17>11,"???") -> ??? | Q17: - | R17: - | S17: 30 | Y17: 2.27 | Z17: - | AA17: -
B18: Unique Sidearms
B19: Buchon Rewards
B20: El General | D20: 4 | E20: 8 | F20: N/A | H20: 3 | I20: 6 | J20: N/A | O20: =IFS(OR(G20="-",ISBLANK(G20)),"-",G20<1,"one-hit",G20<=3,60/L20,OR(G20=4,G20=7,G20=9),"manual",G20<7,2*60/L20,G20<9,3*60/L20,G20<=11,4*60/L20,G20>11,"???") -> - | P20: =IFS(OR(K20="-",ISBLANK(K20)),"-",K20<1,"one-hit",K20<=3,60/L20,OR(K20=4,K20=7,K20=9),"manual",K20<7,2*60/L20,K20<9,3*60/L20,K20<=11,4*60/L20,K20>11,"???") -> - | Q20: - | R20: - | S20: 15 | Y20: - | Z20: - | AA20: -
B21: La Novena | D21: 1 | E21: 3 | F21: N/A | H21: 1 | I21: 3 | J21: N/A | O21: =IFS(OR(G21="-",ISBLANK(G21)),"-",G21<1,"one-hit",G21<=3,60/L21,OR(G21=4,G21=7,G21=9),"manual",G21<7,2*60/L21,G21<9,3*60/L21,G21<=11,4*60/L21,G21>11,"???") -> - | P21: =IFS(OR(K21="-",ISBLANK(K21)),"-",K21<1,"one-hit",K21<=3,60/L21,OR(K21=4,K21=7,K21=9),"manual",K21<7,2*60/L21,K21<9,3*60/L21,K21<=11,4*60/L21,K21>11,"???") -> - | Q21: - | R21: - | S21: 7 | Y21: - | Z21: - | AA21: -
B22: Lady Killer | D22: 4 | E22: 8 | F22: N/A | H22: 3 | I22: 6 | J22: N/A | O22: =IFS(OR(G22="-",ISBLANK(G22)),"-",G22<1,"one-hit",G22<=3,60/L22,OR(G22=4,G22=7,G22=9),"manual",G22<7,2*60/L22,G22<9,3*60/L22,G22<=11,4*60/L22,G22>11,"???") -> - | P22: =IFS(OR(K22="-",ISBLANK(K22)),"-",K22<1,"one-hit",K22<=3,60/L22,OR(K22=4,K22=7,K22=9),"manual",K22<7,2*60/L22,K22<9,3*60/L22,K22<=11,4*60/L22,K22>11,"???") -> - | Q22: - | R22: - | S22: 20 | Y22: - | Z22: - | AA22: -
B23: The BFF | D23: 2 | E23: 4 | F23: N/A | H23: 1 | I23: 3 | J23: N/A | O23: =IFS(OR(G23="-",ISBLANK(G23)),"-",G23<1,"one-hit",G23<=3,60/L23,OR(G23=4,G23=7,G23=9),"manual",G23<7,2*60/L23,G23<9,3*60/L23,G23<=11,4*60/L23,G23>11,"???") -> - | P23: =IFS(OR(K23="-",ISBLANK(K23)),"-",K23<1,"one-hit",K23<=3,60/L23,OR(K23=4,K23=7,K23=9),"manual",K23<7,2*60/L23,K23<9,3*60/L23,K23<=11,4*60/L23,K23>11,"???") -> - | Q23: - | R23: - | S23: 7 | Y23: - | Z23: - | AA23: -
B24: Fallen Ghosts
B25: P227 Urban | F25: N/A | H25: 3 | I25: 7 | J25: N/A | S25: 10
B26: Skorpion Skull | D26: N/A | H26: N/A | J26: 7 | K26: 15 | O26: =IFS(OR(G26="-",ISBLANK(G26)),"-",G26<1,"one-hit",G26<=3,60/L26,OR(G26=4,G26=7,G26=9),"manual",G26<7,2*60/L26,G26<9,3*60/L26,G26<=11,4*60/L26,G26>11,"???") -> - | P26: =IFS(OR(K26="-",ISBLANK(K26)),"-",K26<1,"one-hit",K26<=3,60/L26,OR(K26=4,K26=7,K26=9),"manual",K26<7,2*60/L26,K26<9,3*60/L26,K26<=11,4*60/L26,K26>11,"???") -> ??? | Q26: - | R26: - | S26: 30 | Y26: - | Z26: - | AA26: -
B27: Other
B28: Jackdaw Pistol | F28: N/A | H28: 1 | I28: 2 | J28: N/A | O28: =IFS(OR(G28="-",ISBLANK(G28)),"-",G28<1,"one-hit",G28<=3,60/L28,OR(G28=4,G28=7,G28=9),"manual",G28<7,2*60/L28,G28<9,3*60/L28,G28<=11,4*60/L28,G28>11,"???") -> - | P28: =IFS(OR(K28="-",ISBLANK(K28)),"-",K28<1,"one-hit",K28<=3,60/L28,OR(K28=4,K28=7,K28=9),"manual",K28<7,2*60/L28,K28<9,3*60/L28,K28<=11,4*60/L28,K28>11,"???") -> - | Q28: - | R28: - | S28: 1 | Y28: - | Z28: - | AA28: -
B29: Five-Seven Blacklist | F29: N/A | H29: 3 | I29: 7 | J29: N/A | O29: =IFS(OR(G29="-",ISBLANK(G29)),"-",G29<1,"one-hit",G29<=3,60/L29,OR(G29=4,G29=7,G29=9),"manual",G29<7,2*60/L29,G29<9,3*60/L29,G29<=11,4*60/L29,G29>11,"???") -> - | P29: =IFS(OR(K29="-",ISBLANK(K29)),"-",K29<1,"one-hit",K29<=3,60/L29,OR(K29=4,K29=7,K29=9),"manual",K29<7,2*60/L29,K29<9,3*60/L29,K29<=11,4*60/L29,K29>11,"???") -> - | Q29: - | R29: - | S29: 20 | Y29: - | Z29: - | AA29: -
